Traceback (most recent call last):
  File "/home/codespace/.local/lib/python3.12/site-packages/jupyter_core/utils/__init__.py", line 154, in wrapped
    asyncio.get_running_loop()
RuntimeError: no running event loop

During handling of the above exception, another exception occurred:

Traceback (most recent call last):
  File "/usr/local/python/3.12.1/lib/python3.12/site-packages/jupyter_cache/executors/utils.py", line 58, in single_nb_execution
    executenb(
  File "/home/codespace/.local/lib/python3.12/site-packages/nbclient/client.py", line 1319, in execute
    return NotebookClient(nb=nb, resources=resources, km=km, **kwargs).execute()
           ^^^^^^^^^^^^^^^^^^^^^^^^^^^^^^^^^^^^^^^^^^^^^^^^^^^^^^^^^^^^^^^^^^^^^
  File "/home/codespace/.local/lib/python3.12/site-packages/jupyter_core/utils/__init__.py", line 158, in wrapped
    return loop.run_until_complete(inner)
           ^^^^^^^^^^^^^^^^^^^^^^^^^^^^^^
  File "/usr/local/python/3.12.1/lib/python3.12/asyncio/base_events.py", line 684, in run_until_complete
    return future.result()
           ^^^^^^^^^^^^^^^
  File "/home/codespace/.local/lib/python3.12/site-packages/nbclient/client.py", line 709, in async_execute
    await self.async_execute_cell(
  File "/home/codespace/.local/lib/python3.12/site-packages/nbclient/client.py", line 1062, in async_execute_cell
    await self._check_raise_for_error(cell, cell_index, exec_reply)
  File "/home/codespace/.local/lib/python3.12/site-packages/nbclient/client.py", line 918, in _check_raise_for_error
    raise CellExecutionError.from_cell_and_msg(cell, exec_reply_content)
nbclient.exceptions.CellExecutionError: An error occurred while executing the following cell:
------------------
# BAGGING CLASSIFIER - DATA SMOTE
print("=== BAGGING CLASSIFIER: DATA SMOTE ===")

bagging_smote = BaggingClassifier(
    estimator=GaussianNB(),
    n_estimators=10,
    random_state=42
)

bagging_smote.fit(X_train_smote, y_train_smote)
y_pred_bagging_smote = bagging_smote.predict(X_test_smote)

acc_bagging_smote = accuracy_score(y_test_smote, y_pred_bagging_smote)
print(f"Accuracy Bagging (Data SMOTE): {acc_bagging_smote:.4f}")

print("\nClassification Report Bagging (Data SMOTE):")
print(classification_report(y_test_smote, y_pred_bagging_smote))
------------------

----- stdout -----
=== BAGGING CLASSIFIER: DATA SMOTE ===
------------------

[31m---------------------------------------------------------------------------[39m
[31mNameError[39m                                 Traceback (most recent call last)
[36mCell[39m[36m [39m[32mIn[7][39m[32m, line 4[39m
[32m      1[39m [38;5;66;03m# BAGGING CLASSIFIER - DATA SMOTE[39;00m
[32m      2[39m [38;5;28mprint[39m([33m"[39m[33m=== BAGGING CLASSIFIER: DATA SMOTE ===[39m[33m"[39m)
[32m----> [39m[32m4[39m bagging_smote = [43mBaggingClassifier[49m(
[32m      5[39m     estimator=GaussianNB(),
[32m      6[39m     n_estimators=[32m10[39m,
[32m      7[39m     random_state=[32m42[39m
[32m      8[39m )
[32m     10[39m bagging_smote.fit(X_train_smote, y_train_smote)
[32m     11[39m y_pred_bagging_smote = bagging_smote.predict(X_test_smote)

[31mNameError[39m: name 'BaggingClassifier' is not defined

